Unable to set line 4 to input
Unable to set line 4 to input
Traceback (most recent call last):
  File "/home/yura/dht22/dht22-kafka-producer.py", line 14, in <module>
    temp= dht_device.temperature
  File "/usr/local/lib/python3.8/dist-packages/adafruit_dht.py", line 274, in temperature
    self.measure()
  File "/usr/local/lib/python3.8/dist-packages/adafruit_dht.py", line 258, in measure
    raise RuntimeError("Checksum did not validate. Try again.")
RuntimeError: Checksum did not validate. Try again.

During handling of the above exception, another exception occurred:

Traceback (most recent call last):
  File "/home/yura/dht22/dht22-kafka-producer.py", line 29, in <module>
    print(e, file = sys.stderr)
NameError: name 'e' is not defined
Traceback (most recent call last):
  File "/home/yura/dht22/dht22-kafka-producer.py", line 14, in <module>
    temp= dht_device.temperature
  File "/usr/local/lib/python3.8/dist-packages/adafruit_dht.py", line 274, in temperature
    self.measure()
  File "/usr/local/lib/python3.8/dist-packages/adafruit_dht.py", line 258, in measure
    raise RuntimeError("Checksum did not validate. Try again.")
RuntimeError: Checksum did not validate. Try again.

During handling of the above exception, another exception occurred:

Traceback (most recent call last):
  File "/home/yura/dht22/dht22-kafka-producer.py", line 29, in <module>
    print(e, file = sys.stderr)
NameError: name 'e' is not defined
Traceback (most recent call last):
  File "/home/yura/dht22/dht22-kafka-producer.py", line 14, in <module>
    temp= dht_device.temperature
  File "/usr/local/lib/python3.8/dist-packages/adafruit_dht.py", line 274, in temperature
    self.measure()
  File "/usr/local/lib/python3.8/dist-packages/adafruit_dht.py", line 258, in measure
    raise RuntimeError("Checksum did not validate. Try again.")
RuntimeError: Checksum did not validate. Try again.

During handling of the above exception, another exception occurred:

Traceback (most recent call last):
  File "/home/yura/dht22/dht22-kafka-producer.py", line 29, in <module>
    print(e, file = sys.stderr)
NameError: name 'e' is not defined
Unable to set line 4 to input
Unable to set line 4 to input
Unable to set line 4 to input
Unable to set line 4 to input
Unable to set line 4 to input
